Workbook

Sheet Metas
B2: TODOS OS CANAIS | E2: 46235 | F2: 46266 | G2: 46296 | H2: 46327 | I2: 46357 | J2: 46388 | K2: 46419 | L2: 46447 | M2: 46478 | N2: 46508 | O2: 46539 | P2: 46569
B3: Dias do mês | E3: 31 | F3: 30 | G3: 31 | H3: 30 | I3: 31 | J3: 31 | K3: 28 | L3: 31 | M3: 30 | N3: 31 | O3: 30 | P3: 31
B4: Dias úteis | E4: 21 | F4: 22 | G4: 22 | H4: 21 | I4: 23 | J4: 21 | K4: 20 | L4: 23 | M4: 22 | N4: 21 | O4: 22 | P4: 22
B6: PREMISSAS DE MARKETING | Q6: NOTA: valores atualizados em 10/07/2026 com a nova planilha de keywords (dedup: volume real triplicou para ~2.534 buscas/mês, mas o segmento B2B/PMOC específico continua com volume mínimo — ~68/mês). Sazonalidade mais concentrada em dezembro. Totais anuais não mudam, a distribuição mensal sim. Ver forecast-midia-paga-12-meses.md, seção 'Atualização 10/07/2026'.
B8: Controle investimento (var. %) | C8: =IFERROR(FORMULATEXT(G8),"") | E8: =IFERROR(E9/E9-1,0) | F8: =IFERROR(F9/E9-1,0) | G8: =IFERROR(G9/F9-1,0) | H8: =IFERROR(H9/G9-1,0) | I8: =IFERROR(I9/H9-1,0) | J8: =IFERROR(J9/I9-1,0) | K8: =IFERROR(K9/J9-1,0) | L8: =IFERROR(L9/K9-1,0) | M8: =IFERROR(M9/L9-1,0) | ... P8: =IFERROR(P9/O9-1,0)
B9: Investimento | C9: =IFERROR(FORMULATEXT(G9),"") | E9: ='Previsão Google'!E8+'Previsão Meta'!E8 | F9: ='Previsão Google'!F8+'Previsão Meta'!F8 | G9: ='Previsão Google'!G8+'Previsão Meta'!G8 | H9: ='Previsão Google'!H8+'Previsão Meta'!H8 | I9: ='Previsão Google'!I8+'Previsão Meta'!I8 | J9: ='Previsão Google'!J8+'Previsão Meta'!J8 | K9: ='Previsão Google'!K8+'Previsão Meta'!K8 | L9: ='Previsão Google'!L8+'Previsão Meta'!L8 | ... P9: ='Previsão Google'!P8+'Previsão Meta'!P8
B10: Variação do CPL | C10: =IFERROR(FORMULATEXT(G10),"") | E10: 0.12 | F10: 0.025 | G10: 0.025 | H10: 0.025 | I10: 0.025 | J10: 0.025 | K10: 0 | L10: 0 | M10: 0.025 | N10: 0.025 | O10: 0.025 | P10: 0.025
B11: Custo por Lead | C11: =('Previsão Meta'!C10+'Previsão Google'!E10)/2 | E11: =IFERROR(AVERAGE('Previsão Google'!E10,'Previsão Meta'!E10),0) | F11: =IFERROR(AVERAGE('Previsão Google'!F10,'Previsão Meta'!F10),0) | G11: =IFERROR(AVERAGE('Previsão Google'!G10,'Previsão Meta'!G10),0) | H11: =IFERROR(AVERAGE('Previsão Google'!H10,'Previsão Meta'!H10),0) | I11: =IFERROR(AVERAGE('Previsão Google'!I10,'Previsão Meta'!I10),0) | J11: =IFERROR(AVERAGE('Previsão Google'!J10,'Previsão Meta'!J10),0) | K11: =IFERROR(AVERAGE('Previsão Google'!K10,'Previsão Meta'!K10),0) | L11: =IFERROR(AVERAGE('Previsão Google'!L10,'Previsão Meta'!L10),0) | ... P11: =IFERROR(AVERAGE('Previsão Google'!P10,'Previsão Meta'!P10),0)
B12: Leads Gerados | C12: =IFERROR(FORMULATEXT(G12),"") | E12: =ROUND(E9/E11,0) | F12: =ROUND(F9/F11,0) | G12: =ROUND(G9/G11,0) | H12: =ROUND(H9/H11,0) | I12: =ROUND(I9/I11,0) | J12: =ROUND(J9/J11,0) | K12: =ROUND(K9/K11,0) | L12: =ROUND(L9/L11,0) | ... P12: =ROUND(P9/P11,0)
B14: PREMISSAS DE PRÉ-VENDA
B16: Leads (WhatsApp / Site / Instagram) | C16: =IFERROR(FORMULATEXT(G16),"") | E16: =E12 | F16: =F12 | G16: =G12 | H16: =H12 | I16: =I12 | J16: =J12 | K16: =K12 | L16: =L12 | ... P16: =P12
B17: Leads > MQL | C17: =IFERROR(FORMULATEXT(G17),"") | E17: 0.75 | F17: 0.75 | G17: 0.75 | H17: 0.75 | I17: 0.75 | J17: 0.75 | K17: 0.75 | L17: 0.75 | M17: 0.75 | N17: 0.75 | O17: 0.75 | P17: 0.75
B18: MQL (Qualificados) | C18: =IFERROR(FORMULATEXT(G18),"") | E18: =ROUND((E16*E17),0) | F18: =ROUND((F16*F17),0) | G18: =ROUND((G16*G17),0) | H18: =ROUND((H16*H17),0) | I18: =ROUND((I16*I17),0) | J18: =ROUND((J16*J17),0) | K18: =ROUND((K16*K17),0) | L18: =ROUND((L16*L17),0) | ... P18: =ROUND((P16*P17),0)
B19: MQL > SQL | C19: =IFERROR(FORMULATEXT(G19),"") | E19: 0.35 | F19: 0.35 | G19: 0.35 | H19: 0.35 | I19: 0.35 | J19: 0.35 | K19: 0.35 | L19: 0.35 | M19: 0.35 | N19: 0.35 | O19: 0.35 | P19: 0.35
B20: SQL (Orçamento) | C20: =IFERROR(FORMULATEXT(G20),"") | E20: =ROUND(E18*E19,0) | F20: =ROUND(F18*F19,0) | G20: =ROUND(G18*G19,0) | H20: =ROUND(H18*H19,0) | I20: =ROUND(I18*I19,0) | J20: =ROUND(J18*J19,0) | K20: =ROUND(K18*K19,0) | L20: =ROUND(L18*L19,0) | ... P20: =ROUND(P18*P19,0)
E21: =IFERROR(E20/E16,0)
B22: PREMISSAS DE VENDAS
B24: SQL | C24: =IFERROR(FORMULATEXT(G24),"") | E24: =E20 | F24: =F20 | G24: =G20 | H24: =H20 | I24: =I20 | J24: =J20 | K24: =K20 | L24: =L20 | ... P24: =P20
B25: SQL > Venda | C25: =IFERROR(FORMULATEXT(G25),"") | E25: 0.25 | F25: 0.25 | G25: 0.25 | H25: 0.25 | I25: 0.25 | J25: 0.25 | K25: 0.25 | L25: 0.25 | M25: 0.25 | N25: 0.25 | O25: 0.25 | P25: 0.25
B26: Venda | C26: =IFERROR(FORMULATEXT(G26),"") | E26: =ROUND(E24*E25,0) | F26: =ROUND(F24*F25,0) | G26: =ROUND(G24*G25,0) | H26: =ROUND(H24*H25,0) | I26: =ROUND(I24*I25,0) | J26: =ROUND(J24*J25,0) | K26: =ROUND(K24*K25,0) | L26: =ROUND(L24*L25,0) | ... P26: =ROUND(P24*P25,0)
B27: Ticket Médio | C27: =IFERROR(FORMULATEXT(G27),"") | E27: =D49 | F27: =E27 | G27: =F27 | H27: =G27 | I27: =H27 | J27: =I27 | K27: =J27 | L27: =K27 | M27: =L27 | ... P27: =O27
B28: Faturamento | C28: =IFERROR(FORMULATEXT(G28),"") | E28: =E26*E27 | F28: =F26*F27 | G28: =G26*G27 | H28: =H26*H27 | I28: =I26*I27 | J28: =J26*J27 | K28: =K26*K27 | L28: =L26*L27 | ... P28: =P26*P27
B29: LTV | C29: 23.2 | E29: =E28*$C$29 | F29: =F28*$C$29 | G29: =G28*$C$29 | H29: =H28*$C$29 | I29: =I28*$C$29 | J29: =J28*$C$29 | K29: =K28*$C$29 | L29: =L28*$C$29 | ... P29: =P28*$C$29
B31: KPI
B33: ROAS | E33: =IFERROR(E28/E9,0) | F33: =IFERROR(F28/F9,0) | G33: =IFERROR(G28/G9,0) | H33: =IFERROR(H28/H9,0) | I33: =IFERROR(I28/I9,0) | J33: =IFERROR(J28/J9,0) | K33: =IFERROR(K28/K9,0) | L33: =IFERROR(L28/L9,0) | ... P33: =IFERROR(P28/P9,0)
B34: CPL (CAC) | C34: 0 | E34: =IFERROR(($C$34+E9)/E12,0) | F34: =IFERROR(($C$34+F9)/F12,0) | G34: =IFERROR(($C$34+G9)/G12,0) | H34: =IFERROR(($C$34+H9)/H12,0) | I34: =IFERROR(($C$34+I9)/I12,0) | J34: =IFERROR(($C$34+J9)/J12,0) | K34: =IFERROR(($C$34+K9)/K12,0) | L34: =IFERROR(($C$34+L9)/L12,0) | ... P34: =IFERROR(($C$34+P9)/P12,0)
B35: CPO | E35: =IFERROR(($C$34+E9)/E18,0) | F35: =IFERROR(($C$34+F9)/F18,0) | G35: =IFERROR(($C$34+G9)/G18,0) | H35: =IFERROR(($C$34+H9)/H18,0) | I35: =IFERROR(($C$34+I9)/I18,0) | J35: =IFERROR(($C$34+J9)/J18,0) | K35: =IFERROR(($C$34+K9)/K18,0) | L35: =IFERROR(($C$34+L9)/L18,0) | ... P35: =IFERROR(($C$34+P9)/P18,0)
B36: CPV | E36: =IFERROR(($C$34+E9)/E26,0) | F36: =IFERROR(($C$34+F9)/F26,0) | G36: =IFERROR(($C$34+G9)/G26,0) | H36: =IFERROR(($C$34+H9)/H26,0) | I36: =IFERROR(($C$34+I9)/I26,0) | J36: =IFERROR(($C$34+J9)/J26,0) | K36: =IFERROR(($C$34+K9)/K26,0) | L36: =IFERROR(($C$34+L9)/L26,0) | ... P36: =IFERROR(($C$34+P9)/P26,0)
C42: DESC. | D42: B2B INDUSTRIAL | E42: COMERCIAL GERAL | F42: AVULSO (NÃO PRIORIZADO)
C43: TKM | D43: 714 | E43: 320 | F43: 0
C44: SQL (ORÇAMENOS QUALIFICADOS) | D44: 34 | E44: 86 | F44: 0
C45: TX CONVERSÃO | D45: 0.25 | E45: 0.25 | F45: 0.25
C46: VENDAS | D46: =D44*D45 | E46: =E44*E45 | F46: =F44*F45
C47: FATURAMENTO | D47: =D43*D46 | E47: =E43*E46 | F47: =F43*F46
C49: TICKET MÉDIO BLEND (B2B + COMERCIAL) | D49: =SUM(D47:F47)/SUM(D46:F46)

Sheet Previsão Meta
B1: META | E1: 46235 | F1: 46266 | G1: 46296 | H1: 46327 | I1: 46357 | J1: 46388 | K1: 46419 | L1: 46447 | M1: 46478 | N1: 46508 | O1: 46539 | P1: 46569
B2: Dias do mês | E2: 31 | F2: 30 | G2: 31 | H2: 30 | I2: 31 | J2: 31 | K2: 28 | L2: 31 | M2: 30 | N2: 31 | O2: 30 | P2: 31
B3: Dias úteis | E3: 21 | F3: 22 | G3: 22 | H3: 21 | I3: 23 | J3: 21 | K3: 20 | L3: 23 | M3: 22 | N3: 21 | O3: 22 | P3: 22
B5: PREMISSAS DE MARKETING
B7: Controle investimento | C7: =IFERROR(FORMULATEXT(G7),"") | E7: 0 | F7: =IFERROR(F8/E8-1,0) | G7: =IFERROR(G8/F8-1,0) | H7: =IFERROR(H8/G8-1,0) | I7: =IFERROR(I8/H8-1,0) | J7: =IFERROR(J8/I8-1,0) | K7: =IFERROR(K8/J8-1,0) | L7: =IFERROR(L8/K8-1,0) | M7: =IFERROR(M8/L8-1,0) | ... P7: =IFERROR(P8/O8-1,0)
B8: Investimento | C8: =IFERROR(FORMULATEXT(G8),"") | E8: 0 | F8: 0 | G8: 0 | H8: 0 | I8: 0 | J8: 0 | K8: 0 | L8: 0 | M8: 0 | N8: 0 | O8: 0 | P8: 0
B9: Variação do CPL | C9: =IFERROR(FORMULATEXT(G9),"") | E9: 0 | F9: =IFERROR(F10/E10-1,0) | G9: =IFERROR(G10/F10-1,0) | H9: =IFERROR(H10/G10-1,0) | I9: =IFERROR(I10/H10-1,0) | J9: =IFERROR(J10/I10-1,0) | K9: =IFERROR(K10/J10-1,0) | L9: =IFERROR(L10/K10-1,0) | M9: =IFERROR(M10/L10-1,0) | ... P9: =IFERROR(P10/O10-1,0)
B10: Custo por Lead | C10: 180 | E10: 180 | F10: 180 | G10: 180 | H10: 180 | I10: 180 | J10: 180 | K10: 180 | L10: 180 | M10: 180 | N10: 180 | O10: 180 | P10: 180
B11: Leads Gerados | C11: =IFERROR(FORMULATEXT(G11),"") | E11: =IFERROR(ROUND(E8/E10,0),0) | F11: =IFERROR(ROUND(F8/F10,0),0) | G11: =IFERROR(ROUND(G8/G10,0),0) | H11: =IFERROR(ROUND(H8/H10,0),0) | I11: =IFERROR(ROUND(I8/I10,0),0) | J11: =IFERROR(ROUND(J8/J10,0),0) | K11: =IFERROR(ROUND(K8/K10,0),0) | L11: =IFERROR(ROUND(L8/L10,0),0) | ... P11: =IFERROR(ROUND(P8/P10,0),0)
B13: PREMISSAS DE PRÉ-VENDA
B15: Leads (WhatsApp / Site / Instagram) | C15: =IFERROR(FORMULATEXT(G15),"") | E15: =E11 | F15: =F11 | G15: =G11 | H15: =H11 | I15: =I11 | J15: =J11 | K15: =K11 | L15: =L11 | ... P15: =P11
B16: Leads > MQL | C16: =IFERROR(FORMULATEXT(G16),"") | E16: 0.75 | F16: 0.75 | G16: 0.75 | H16: 0.75 | I16: 0.75 | J16: 0.75 | K16: 0.75 | L16: 0.75 | M16: 0.75 | N16: 0.75 | O16: 0.75 | P16: 0.75
B17: MQL (Qualificados) | C17: =IFERROR(FORMULATEXT(G17),"") | E17: =ROUND((E15*E16),0) | F17: =ROUND((F15*F16),0) | G17: =ROUND((G15*G16),0) | H17: =ROUND((H15*H16),0) | I17: =ROUND((I15*I16),0) | J17: =ROUND((J15*J16),0) | K17: =ROUND((K15*K16),0) | L17: =ROUND((L15*L16),0) | ... P17: =ROUND((P15*P16),0)
B18: MQL > SQL | C18: =IFERROR(FORMULATEXT(G18),"") | E18: 0.35 | F18: 0.35 | G18: 0.35 | H18: 0.35 | I18: 0.35 | J18: 0.35 | K18: 0.35 | L18: 0.35 | M18: 0.35 | N18: 0.35 | O18: 0.35 | P18: 0.35
B19: SQL (Orçamento) | C19: =IFERROR(FORMULATEXT(G19),"") | E19: =ROUND(E17*E18,0) | F19: =ROUND(F17*F18,0) | G19: =ROUND(G17*G18,0) | H19: =ROUND(H17*H18,0) | I19: =ROUND(I17*I18,0) | J19: =ROUND(J17*J18,0) | K19: =ROUND(K17*K18,0) | L19: =ROUND(L17*L18,0) | ... P19: =ROUND(P17*P18,0)
E20: =IFERROR(E19/E15,0)
B21: PREMISSAS DE VENDAS
B23: SQL | C23: =IFERROR(FORMULATEXT(G23),"") | E23: =E19 | F23: =F19 | G23: =G19 | H23: =H19 | I23: =I19 | J23: =J19 | K23: =K19 | L23: =L19 | ... P23: =P19
B24: SQL > Venda | C24: =IFERROR(FORMULATEXT(G24),"") | E24: 0.25 | F24: 0.25 | G24: 0.25 | H24: 0.25 | I24: 0.25 | J24: 0.25 | K24: 0.25 | L24: 0.25 | M24: 0.25 | N24: 0.25 | O24: 0.25 | P24: 0.25
B25: Venda | C25: =IFERROR(FORMULATEXT(G25),"") | E25: =ROUND(E23*E24,0) | F25: =ROUND(F23*F24,0) | G25: =ROUND(G23*G24,0) | H25: =ROUND(H23*H24,0) | I25: =ROUND(I23*I24,0) | J25: =ROUND(J23*J24,0) | K25: =ROUND(K23*K24,0) | L25: =ROUND(L23*L24,0) | ... P25: =ROUND(P23*P24,0)
B26: Ticket Médio | C26: =IFERROR(FORMULATEXT(G26),"") | E26: 320 | F26: =E26 | G26: =F26 | H26: =G26 | I26: =H26 | J26: =I26 | K26: =J26 | L26: =K26 | M26: =L26 | ... P26: =O26
B27: Faturamento | C27: =IFERROR(FORMULATEXT(G27),"") | E27: =E25*E26 | F27: =F25*F26 | G27: =G25*G26 | H27: =H25*H26 | I27: =I25*I26 | J27: =J25*J26 | K27: =K25*K26 | L27: =L25*L26 | ... P27: =P25*P26
B28: LTV (meses) | C28: 12 | D28: 12 meses (conservador, mesmo horizonte do segmento Comercial Geral em Google) — não aplicável na prática, já que o investimento recomendado é R$0. | E28: =E27*$C$28 | F28: =F27*$C$28 | G28: =G27*$C$28 | H28: =H27*$C$28 | I28: =I27*$C$28 | J28: =J27*$C$28 | K28: =K27*$C$28 | L28: =L27*$C$28 | ... P28: =P27*$C$28
B30: KPI
B32: ROAS | E32: =IFERROR(E27/E8,0) | F32: =IFERROR(F27/F8,0) | G32: =IFERROR(G27/G8,0) | H32: =IFERROR(H27/H8,0) | I32: =IFERROR(I27/I8,0) | J32: =IFERROR(J27/J8,0) | K32: =IFERROR(K27/K8,0) | L32: =IFERROR(L27/L8,0) | ... P32: =IFERROR(P27/P8,0)
B33: CPL (CAC) | C33: 0 | E33: =IFERROR(($C$33+E8)/E11,0) | F33: =IFERROR(($C$33+F8)/F11,0) | G33: =IFERROR(($C$33+G8)/G11,0) | H33: =IFERROR(($C$33+H8)/H11,0) | I33: =IFERROR(($C$33+I8)/I11,0) | J33: =IFERROR(($C$33+J8)/J11,0) | K33: =IFERROR(($C$33+K8)/K11,0) | L33: =IFERROR(($C$33+L8)/L11,0) | ... P33: =IFERROR(($C$33+P8)/P11,0)
B34: CPO | E34: =IFERROR(($C$33+E8)/E17,0) | F34: =IFERROR(($C$33+F8)/F17,0) | G34: =IFERROR(($C$33+G8)/G17,0) | H34: =IFERROR(($C$33+H8)/H17,0) | I34: =IFERROR(($C$33+I8)/I17,0) | J34: =IFERROR(($C$33+J8)/J17,0) | K34: =IFERROR(($C$33+K8)/K17,0) | L34: =IFERROR(($C$33+L8)/L17,0) | ... P34: =IFERROR(($C$33+P8)/P17,0)
B35: CPV | E35: =IFERROR(($C$33+E8)/E25,0) | F35: =IFERROR(($C$33+F8)/F25,0) | G35: =IFERROR(($C$33+G8)/G25,0) | H35: =IFERROR(($C$33+H8)/H25,0) | I35: =IFERROR(($C$33+I8)/I25,0) | J35: =IFERROR(($C$33+J8)/J25,0) | K35: =IFERROR(($C$33+K8)/K25,0) | L35: =IFERROR(($C$33+L8)/L25,0) | ... P35: =IFERROR(($C$33+P8)/P25,0)
B38: PREMISSAS DE MARKETING | D38: OBSERVAÇÕES
B39: Controle investimento | D39: RECOMENDAÇÃO: não investir em Meta Ads para captação fria neste cenário. Rodando o mesmo funil melhorado (scoring + scripts SDR) com Meta, o ROAS-LTV projetado é de apenas 1,4x — abaixo do piso saudável de mercado (1:3) e muito inferior ao Google Ads (4,6x-12,1x). Consistente com o diagnóstico de marketing (S3): Meta funciona melhor como remarketing do que captação fria para este perfil B2B/nicho.
B40: Investimento | D40: Investimento zerado em todos os meses — é a recomendação. As linhas de CPL/funil abaixo ficam preenchidas como referência, caso o operador decida testar um orçamento pequeno de remarketing no futuro (não modelado aqui).
B41: Variação do CPL | D41: Não aplicável com investimento zerado — mantido por consistência de fórmula.
B42: Custo por Lead | D42: R$180/lead — benchmark internacional Meta Ads B2B (serviços profissionais/home services, US$30-50+, convertido a ~R$5,15/USD), MUITO mais caro que o CPL de Google Ads para este nicho.
B43: Leads Gerados | D43: Fórmula protegida com IFERROR — com investimento R$0, leads gerados = 0.
B45: PREMISSAS DE PRÉ-VENDA | D45: OBSERVAÇÕES
B46: Leads (No Kommo) | D46: Não aplicável — sem investimento, sem leads.
B47: Leads > MQL | D47: Mantido como referência de benchmark (75%, igual ao cenário melhorado de Google), caso o canal seja testado no futuro.
B48: MQL (Cadastro no Moskit) | D48: Quantidade de negócios cadastrados no Moskit, conforme a taxa de conversão das conversas que passam do Kommo (atendimento) para o CRM (Moskit).
B49: MQL > SQL | D49: Mantido como referência de benchmark (35%), igual ao cenário melhorado de Google.
B50: SQL (Orçamento) | D50: Não aplicável — sem investimento, sem SQL.
...

Sheet Previsão Google
B1: GOOGLE | E1: 46235 | F1: 46266 | G1: 46296 | H1: 46327 | I1: 46357 | J1: 46388 | K1: 46419 | L1: 46447 | M1: 46478 | N1: 46508 | O1: 46539 | P1: 46569
B2: Dias do mês | E2: 31 | F2: 30 | G2: 31 | H2: 30 | I2: 31 | J2: 31 | K2: 28 | L2: 31 | M2: 30 | N2: 31 | O2: 30 | P2: 31
B3: Dias úteis | E3: 21 | F3: 22 | G3: 22 | H3: 21 | I3: 23 | J3: 21 | K3: 20 | L3: 23 | M3: 22 | N3: 21 | O3: 22 | P3: 22
B5: PREMISSAS DE MARKETING
B7: Controle investimento | C7: =IFERROR(FORMULATEXT(G7),"") | E7: 0 | F7: =IFERROR(F8/E8-1,0) | G7: =IFERROR(G8/F8-1,0) | H7: =IFERROR(H8/G8-1,0) | I7: =IFERROR(I8/H8-1,0) | J7: =IFERROR(J8/I8-1,0) | K7: =IFERROR(K8/J8-1,0) | L7: =IFERROR(L8/K8-1,0) | M7: =IFERROR(M8/L8-1,0) | ... P7: =IFERROR(P8/O8-1,0)
B8: Investimento | C8: =IFERROR(FORMULATEXT(G8),"") | E8: 2259 | F8: 2826 | G8: 3112 | H8: 3628 | I8: 5651 | J8: 4008 | K8: 3493 | L8: 2889 | M8: 2250 | N8: 1799 | O8: 1905 | P8: 2178
B9: Variação do CPL | C9: =IFERROR(FORMULATEXT(G9),"") | E9: 0 | F9: =IFERROR(F10/E10-1,0) | G9: =IFERROR(G10/F10-1,0) | H9: =IFERROR(H10/G10-1,0) | I9: =IFERROR(I10/H10-1,0) | J9: =IFERROR(J10/I10-1,0) | K9: =IFERROR(K10/J10-1,0) | L9: =IFERROR(L10/K10-1,0) | M9: =IFERROR(M10/L10-1,0) | ... P9: =IFERROR(P10/O10-1,0)
B10: Custo por Lead | E10: 82.93 | F10: 79.69 | G10: 78.56 | H10: 77.03 | I10: 73.94 | J10: 76.19 | K10: 77.38 | L10: 79.42 | M10: 82.99 | N10: 87.47 | O10: 86.17 | P10: 83.56
B11: Leads Gerados | C11: =IFERROR(FORMULATEXT(G11),"") | E11: =ROUND(E8/E10,0) | F11: =ROUND(F8/F10,0) | G11: =ROUND(G8/G10,0) | H11: =ROUND(H8/H10,0) | I11: =ROUND(I8/I10,0) | J11: =ROUND(J8/J10,0) | K11: =ROUND(K8/K10,0) | L11: =ROUND(L8/L10,0) | ... P11: =ROUND(P8/P10,0)
B13: PREMISSAS DE PRÉ-VENDA
B15: Leads (WhatsApp / Site / Instagram) | C15: =IFERROR(FORMULATEXT(G15),"") | E15: =E11 | F15: =F11 | G15: =G11 | H15: =H11 | I15: =I11 | J15: =J11 | K15: =K11 | L15: =L11 | ... P15: =P11
B16: Leads > MQL | C16: =IFERROR(FORMULATEXT(G16),"") | E16: 0.75 | F16: 0.75 | G16: 0.75 | H16: 0.75 | I16: 0.75 | J16: 0.75 | K16: 0.75 | L16: 0.75 | M16: 0.75 | N16: 0.75 | O16: 0.75 | P16: 0.75
B17: MQL (Qualificados) | C17: =IFERROR(FORMULATEXT(G17),"") | E17: =ROUND((E15*E16),0) | F17: =ROUND((F15*F16),0) | G17: =ROUND((G15*G16),0) | H17: =ROUND((H15*H16),0) | I17: =ROUND((I15*I16),0) | J17: =ROUND((J15*J16),0) | K17: =ROUND((K15*K16),0) | L17: =ROUND((L15*L16),0) | ... P17: =ROUND((P15*P16),0)
B18: MQL > SQL | C18: =IFERROR(FORMULATEXT(G18),"") | E18: 0.35 | F18: 0.35 | G18: 0.35 | H18: 0.35 | I18: 0.35 | J18: 0.35 | K18: 0.35 | L18: 0.35 | M18: 0.35 | N18: 0.35 | O18: 0.35 | P18: 0.35
B19: SQL (Orçamento) | C19: =IFERROR(FORMULATEXT(G19),"") | E19: =ROUND(E17*E18,0) | F19: =ROUND(F17*F18,0) | G19: =ROUND(G17*G18,0) | H19: =ROUND(H17*H18,0) | I19: =ROUND(I17*I18,0) | J19: =ROUND(J17*J18,0) | K19: =ROUND(K17*K18,0) | L19: =ROUND(L17*L18,0) | ... P19: =ROUND(P17*P18,0)
E20: =IFERROR(E19/E15,0)
B21: PREMISSAS DE VENDAS
B23: SQL | C23: =IFERROR(FORMULATEXT(G23),"") | E23: =E19 | F23: =F19 | G23: =G19 | H23: =H19 | I23: =I19 | J23: =J19 | K23: =K19 | L23: =L19 | ... P23: =P19
B24: SQL > Venda | C24: =IFERROR(FORMULATEXT(G24),"") | E24: 0.25 | F24: 0.25 | G24: 0.25 | H24: 0.25 | I24: 0.25 | J24: 0.25 | K24: 0.25 | L24: 0.25 | M24: 0.25 | N24: 0.25 | O24: 0.25 | P24: 0.25
B25: Venda | C25: =IFERROR(FORMULATEXT(G25),"") | E25: =ROUND(E23*E24,0) | F25: =ROUND(F23*F24,0) | G25: =ROUND(G23*G24,0) | H25: =ROUND(H23*H24,0) | I25: =ROUND(I23*I24,0) | J25: =ROUND(J23*J24,0) | K25: =ROUND(K23*K24,0) | L25: =ROUND(L23*L24,0) | ... P25: =ROUND(P23*P24,0)
B26: Ticket Médio | C26: =IFERROR(FORMULATEXT(G26),"") | E26: =Metas!D49 | F26: =E26 | G26: =F26 | H26: =G26 | I26: =H26 | J26: =I26 | K26: =J26 | L26: =K26 | M26: =L26 | ... P26: =O26
B27: Faturamento | C27: =IFERROR(FORMULATEXT(G27),"") | E27: =E25*E26 | F27: =F25*F26 | G27: =G25*G26 | H27: =H25*H26 | I27: =I25*I26 | J27: =J25*J26 | K27: =K25*K26 | L27: =L25*L26 | ... P27: =P25*P26
B28: LTV (meses) | C28: 23.2 | D28: Horizonte médio ponderado por receita: 23.2 meses, entre 12 meses (Comercial Geral, conservador) e 36 meses (B2B Industrial — JK relata só 2 empresas perdidas DESDE SEMPRE, muito acima do benchmark de mercado B2B de ~72,5% retenção/ano). Recalibrar quando ee-s3-crm-setup existir e houver churn real medido. | E28: =E27*$C$28 | F28: =F27*$C$28 | G28: =G27*$C$28 | H28: =H27*$C$28 | I28: =I27*$C$28 | J28: =J27*$C$28 | K28: =K27*$C$28 | L28: =L27*$C$28 | ... P28: =P27*$C$28
B30: KPI
B32: ROAS | E32: =IFERROR(E27/E8,0) | F32: =IFERROR(F27/F8,0) | G32: =IFERROR(G27/G8,0) | H32: =IFERROR(H27/H8,0) | I32: =IFERROR(I27/I8,0) | J32: =IFERROR(J27/J8,0) | K32: =IFERROR(K27/K8,0) | L32: =IFERROR(L27/L8,0) | ... P32: =IFERROR(P27/P8,0)
B33: CPL (CAC) | C33: 0 | E33: =IFERROR(($C$33+E8)/E11,0) | F33: =IFERROR(($C$33+F8)/F11,0) | G33: =IFERROR(($C$33+G8)/G11,0) | H33: =IFERROR(($C$33+H8)/H11,0) | I33: =IFERROR(($C$33+I8)/I11,0) | J33: =IFERROR(($C$33+J8)/J11,0) | K33: =IFERROR(($C$33+K8)/K11,0) | L33: =IFERROR(($C$33+L8)/L11,0) | ... P33: =IFERROR(($C$33+P8)/P11,0)
B34: CPO | E34: =IFERROR(($C$33+E8)/E17,0) | F34: =IFERROR(($C$33+F8)/F17,0) | G34: =IFERROR(($C$33+G8)/G17,0) | H34: =IFERROR(($C$33+H8)/H17,0) | I34: =IFERROR(($C$33+I8)/I17,0) | J34: =IFERROR(($C$33+J8)/J17,0) | K34: =IFERROR(($C$33+K8)/K17,0) | L34: =IFERROR(($C$33+L8)/L17,0) | ... P34: =IFERROR(($C$33+P8)/P17,0)
B35: CPV | E35: =IFERROR(($C$33+E8)/E25,0) | F35: =IFERROR(($C$33+F8)/F25,0) | G35: =IFERROR(($C$33+G8)/G25,0) | H35: =IFERROR(($C$33+H8)/H25,0) | I35: =IFERROR(($C$33+I8)/I25,0) | J35: =IFERROR(($C$33+J8)/J25,0) | K35: =IFERROR(($C$33+K8)/K25,0) | L35: =IFERROR(($C$33+L8)/L25,0) | ... P35: =IFERROR(($C$33+P8)/P25,0)
B38: PREMISSAS DE MARKETING | D38: OBSERVAÇÕES
B39: Controle investimento | D39: Investimento 100% em Google Ads (Search) — nenhum orçamento alocado em Meta Ads neste cenário. Ver forecast-midia-paga-12-meses.md para a justificativa completa (ROAS-LTV de Meta ficou em 1,4x, abaixo do piso saudável de mercado de 1:3).
B40: Investimento | D40: Orçamento mensal recalculado em 10/07/2026 com a planilha de keywords nova (1.517 linhas, deduplicada por cluster de variantes). Sazonalidade ficou mais concentrada em dezembro (índice 218 vs 170 da versão anterior) — dezembro passa a ser 15,7% do orçamento anual. Piso de R$1.500/mês por segmento mantido, pico ainda em dez/26-jan/27.
B41: Variação do CPL | D41: CPL blend varia mês a mês conforme o mix de leads entre o segmento Comercial Geral (CPL R$55, mais barato, mais volume) e B2B Industrial (CPL R$140, benchmark Brasil 2026 de R$80-200/lead) — não é uma taxa de crescimento fixa, é resultado direto do mix sazonal dos dois segmentos.
B42: Custo por Lead | D42: CPL Comercial R$55 estimado a partir do CPC observado na planilha de keywords + CVR típico de página (~10%, benchmark WordStream 8,18% global). CPL B2B R$140 vem de benchmark de mercado (Google Ads Brasil, Indústria/Manufatura: CPL R$80-200).
B43: Leads Gerados | D43: CPL blend recalculado com mais dados reais de lance (14 de 1.517 keywords, era 3 de 535). Faixa de CPC ficou um pouco mais ampla no topo (até R$67,62 para termos de 'instalação' mais disputados) — CPL Comercial R$55 mantido como estimativa central, mas monitorar de perto assim que a campanha estiver no ar, já que 'instalação' é agora o maior cluster de demanda da planilha.
B45: PREMISSAS DE PRÉ-VENDA | D45: OBSERVAÇÕES
B46: Leads (No Kommo) | D46: Leads que chegam por WhatsApp direto, Instagram ou formulário do site — JK não tem CRM/Kommo hoje (ver ee-s4-diagnostico-comercial). Recomendação: implementar CRM leve (ee-s3-crm-setup, pendente) para rastrear isso de verdade.
B47: Leads > MQL | D47: Estimativa: 65% sem scoring formal (cenário hoje) a 75% com o scoring 1-5⭐ e os scripts de qualificação já entregues em ee-s4-diagnostico-comercial/ee-s5-scripts-sdr. Esta planilha usa o cenário MELHORADO (75%).
B48: MQL (Cadastro no Moskit) | D48: MQL = lead que passou pela qualificação básica (perfil, raio de atuação, tipo de serviço) segundo os scripts de ee-s5-scripts-sdr.
B49: MQL > SQL | D49: Benchmark RD Station Panorama Marketing e Vendas 2026: MQL→SQL <15% fraco, 15-25% médio (situação da JK hoje, sem SLA formal), 35-50% em B2B com SLA marketing-vendas formalizado. Usamos 35% (piso da faixa 'com SLA'), pressupondo que o scoring/cadência de ee-s5-scripts-sdr está em uso.
B50: SQL (Orçamento) | D50: SQL = lead que recebeu orçamento formal e está em negociação ativa.
...
