Workbook

Sheet TABELA DE TELAS
A1: CAMPO | E1: ABA | F1: CÉLULA | G1: FÓRMULA
A2: Perfil Base | B2: ! | C2: " & | D2: & " | E2: USE CASE MAP | F2: B3 | G2: =CONCATENATE(C2,E2,B2,F2,D2) -> " & USE CASE MAP!B3 & "
A3: Motivações | B3: ! | C3: " & | D3: & " | E3: USE CASE MAP | F3: C3 | G3: =CONCATENATE(C3,E3,B3,F3,D3) -> " & USE CASE MAP!C3 & "
A4: Desafios | B4: ! | C4: " & | D4: & " | E4: USE CASE MAP | F4: D3 | G4: =CONCATENATE(C4,E4,B4,F4,D4) -> " & USE CASE MAP!D3 & "
A5: Dores | B5: ! | C5: " & | D5: & " | E5: USE CASE MAP | F5: E3 | G5: =CONCATENATE(C5,E5,B5,F5,D5) -> " & USE CASE MAP!E3 & "
A6: Necessidades | B6: ! | C6: " & | D6: & " | E6: USE CASE MAP | F6: F3 | G6: =CONCATENATE(C6,E6,B6,F6,D6) -> " & USE CASE MAP!F3 & "
A7: Desejos | B7: ! | C7: " & | D7: & " | E7: USE CASE MAP | F7: G3 | G7: =CONCATENATE(C7,E7,B7,F7,D7) -> " & USE CASE MAP!G3 & "
A8: Comunicação | B8: ! | C8: " & | D8: & " | E8: USE CASE MAP | F8: H3 | G8: =CONCATENATE(C8,E8,B8,F8,D8) -> " & USE CASE MAP!H3 & "
A9: Problema | B9: ! | C9: " & | D9: & " | E9: USE CASE MAP | F9: B7 | G9: =CONCATENATE(C9,E9,B9,F9,D9) -> " & USE CASE MAP!B7 & "
A10: Contexto | B10: ! | C10: " & | D10: & " | E10: USE CASE MAP | F10: C7 | G10: =CONCATENATE(C10,E10,B10,F10,D10) -> " & USE CASE MAP!C7 & "
A11: Como Lida Hoje | B11: ! | C11: " & | D11: & " | E11: USE CASE MAP | F11: D7 | G11: =CONCATENATE(C11,E11,B11,F11,D11) -> " & USE CASE MAP!D7 & "
A12: Expressão da Dor | B12: ! | C12: " & | D12: & " | E12: USE CASE MAP | F12: E7 | G12: =CONCATENATE(C12,E12,B12,F12,D12) -> " & USE CASE MAP!E7 & "
A13: Causa Raiz | B13: ! | C13: " & | D13: & " | E13: USE CASE MAP | F13: F7 | G13: =CONCATENATE(C13,E13,B13,F13,D13) -> " & USE CASE MAP!F7 & "
... A86: Categoria 3 Pilar 3 Tema 3 | B86: ! | C86: " & | D86: & " | E86: LINHA EDITORIAL | F86: D23 | G86: =CONCATENATE(C86,E86,B86,F86,D86) -> " & LINHA EDITORIAL!D23 & "

Sheet POSICIONAMENTO
B1: ORIENTAÇÕES BÁSICAS
A2: Aspecto | B2: NOME DO CLIENTE | C2: REGIÃO DE ATENDIMENTO | D2: MODELO DE NEGÓCIO | E2: SETOR | F2: PRODUTO | SERVIÇO | G2: SAZONALIDADE
A3: Detalhamento | B3: MINA PIZZA | C3: São Vicente - SP | D3: Negócio Local (loja física, restaurante, clínica etc.) | E3: Alimentação | F3: Pizzas, Marmitas, Pastéis e Refeições Delivery | G3: Não Temos Sazonalidade
B5: ESTRATÉGIA
A6: Aspecto | B6: TOM DE VOZ | C6: NÍVEL DE LINGUAGEM | D6: COMO O PÚBLICO PRECISA SE SENTIR AO VER O CONTEÚDO? | E6: CONTEÚDOS POR MÊS | F6: EXPRESSÔES CHAVE | G6: PALAVRA CHAVE EM FOCO
A7: Detalhamento | B7: Próximo, acolhedor e tradicional | C7: Simples e objetiva, com linguagem regional e foco em confiança e tradição | D7: Que encontrou um restaurante de confiança, com tradição, atendimento próximo e comida de qualidade para compartilhar com a família sem preocupação. | E7: 3 Conteúdos por Semana | F7: "O sabor que faz parte da história de São Vicente." • "Pizza boa é aquela que reúne a família." • "Tradição que continua na sua mesa." • "Peça pelo WhatsApp de forma rápida e fácil." • "Almoço caseiro, pizza de verdade e atendimento de quem conhece você." | G7: Pizza Delivery São Vicente

Sheet USE CASE MAP
B1: PÚBLICO ALVO
A2: Aspecto | B2: Perfil Base | C2: Motivações | D2: Desafios | E2: Dores | F2: Necessidades | G2: Desejos | H2: Comunicação
A3: Detalhamento | B3: O público principal da Mina Pizza não procura apenas uma pizzaria. Ele procura um estabelecimento que já faz parte da rotina da família e transmite confiança. São moradores de São Vicente e cidades próximas que trabalham durante o dia, possuem pouco tempo para cozinhar e valorizam estabelecimentos tradicionais que entreguem qualidade consistente sem complicação. Grande parte desse público conheceu a empresa por indicação, pela localização ou por muitos anos de operação. Não é um consumidor que busca tendências gastronômicas ou restaurantes "instagramáveis". Seu comportamento é orientado por previsibilidade: ele prefere comprar onde já sabe que será bem atendido e receberá um produto que conhece. Além da pizza, existe uma oportunidade importante de expansão por meio das marmitas e refeições do dia, aproveitando um hábito de consumo recorrente durante a semana, estratégia já identificada nas reuniões de planejamento. | C3: O principal objetivo desse cliente é resolver uma necessidade cotidiana de alimentação com rapidez, praticidade e segurança. Ele deseja evitar o desgaste de cozinhar, ganhar tempo após um dia de trabalho e alimentar a família sem correr riscos ao experimentar locais desconhecidos. Quando pede uma pizza, busca um momento de lazer e convivência familiar. Quando compra uma marmita, procura uma solução prática para o almoço sem perder a sensação de comida caseira. Existe também uma motivação emocional importante: consumir em um local tradicional reforça a sensação de pertencimento e continuidade de uma rotina construída ao longo dos anos. | D3: Embora seja um cliente fiel, sua permanência não é garantida. O aumento das opções de delivery e a facilidade de comparação entre restaurantes tornam a experiência de atendimento um fator decisivo. Nas reuniões foram identificados desafios operacionais que impactam diretamente essa percepção, como dificuldades no atendimento telefônico, demora na resposta, falta de padronização e limitações nos canais digitais. Outro desafio é que esse público não deseja aprender processos novos para fazer um pedido. Quanto mais simples for a jornada — especialmente via WhatsApp — maior tende a ser a conversão. Essa necessidade de simplificação também foi destacada durante o diagnóstico. | E3: A principal dor não está relacionada apenas ao produto, mas à experiência completa. Quando decide pedir comida, o cliente espera rapidez, clareza e cordialidade. Qualquer atrito durante esse processo reduz sua confiança na marca. As reuniões identificaram reclamações recorrentes envolvendo atendimento telefônico ríspido, demora, falta de informações sobre produtos e dificuldades durante o pedido, pontos confirmados tanto pelas avaliações públicas quanto pelo teste de cliente oculto. Algumas expressões que representam esse sentimento são: "Toda vez preciso ligar mais de uma vez." "Nunca sei quais pratos têm hoje." "Quem atende parece estar com pressa." "Achei que a qualidade caiu." "Está ficando caro pelo que entrega." "Prefiro pedir onde respondem mais rápido." | F3: Mais do que alimentação, esse cliente precisa de previsibilidade. Ele deseja encontrar facilmente a empresa no Google, visualizar o cardápio atualizado, receber atendimento rápido pelo WhatsApp, ter informações claras sobre preços e opções disponíveis e concluir o pedido sem esforço. Também existe uma necessidade crescente de relacionamento. O público valoriza sentir que é reconhecido, lembrado e respeitado durante o atendimento, aspecto discutido na aplicação da metodologia Jobs to Be Done durante a consultoria. | G3: O cliente deseja manter a confiança construída ao longo dos anos, mas espera perceber evolução na empresa. Ele quer continuar comprando na Mina Pizza sabendo que encontrará uma operação mais moderna, organizada e eficiente, sem perder a tradição que o fez se tornar cliente. Também busca praticidade para repetir pedidos, receber novidades, promoções e cardápios sem precisar procurar informações em diversos canais. Essa combinação entre tradição e modernização foi definida como o posicionamento estratégico de "tradição redescoberta" nas reuniões de diagnóstico. | H3: A comunicação ideal para esse público deve ser simples, objetiva e acolhedora. O diagnóstico concluiu que o cliente da Mina Pizza responde melhor a uma linguagem direta, evitando excesso de memes, tendências ou conteúdos excessivamente informais. A recomendação foi priorizar clareza, tradição e proximidade no tom de voz da marca. Esse público costuma utilizar expressões como: "Vou pedir a pizza de sempre." "Tem marmita hoje?" "Manda o cardápio no WhatsApp." "Quanto tempo demora?" "Vocês entregam aqui?" "Quero uma comida boa sem complicação." Essa forma de comunicação demonstra que o cliente valoriza objetividade e conveniência, e espera que a empresa acompanhe esse mesmo padrão em todos os pontos de contato.
B5: PROBLEMA | H5: PERSONA
A6: Aspecto | B6: Problema | C6: Contexto | D6: Como Lida Hoje | E6: Expressão da Dor | F6: Causa Raiz | G6: Frequência | H6: Persona Modelo Base
A7: Detalhamento | B7: A Mina Pizza possui uma marca tradicional e reconhecida localmente, porém sua operação digital e parte da experiência de atendimento ainda não acompanham as expectativas atuais do consumidor. Isso gera um cenário em que novos clientes encontram barreiras para conhecer a empresa, enquanto clientes antigos percebem inconsistências que podem comprometer sua fidelidade. O problema deixa de ser apenas operacional e passa a impactar diretamente o crescimento do negócio. O diagnóstico também mostrou baixa maturidade digital, com deficiência na gestão do Google Meu Negócio, ausência de campanhas estruturadas, pouca constância nas redes sociais e dependência elevada de plataformas terceiras. | C7: Durante muitos anos, a Mina Pizza construiu sua clientela principalmente pela localização, tradição e indicação. Esse modelo foi suficiente enquanto o comportamento de compra era predominantemente presencial ou telefônico. Entretanto, o mercado mudou. Hoje, antes de escolher um restaurante, o consumidor pesquisa no Google, compara avaliações, consulta fotos, verifica horários, busca facilidade para pedir e espera respostas rápidas pelos canais digitais. Nas reuniões foi constatado que existiam problemas como localização incorreta no Google, avaliações sem resposta, Instagram desatualizado, inconsistências de identidade da marca e limitações na apresentação do cardápio digital. Esses fatores reduzem a confiança de novos consumidores antes mesmo do primeiro pedido. Ao mesmo tempo, concorrentes investem continuamente em Google Ads, Meta Ads, presença digital e conteúdos visuais, aumentando sua vantagem competitiva. | D7: Na ausência de uma experiência digital consistente, o cliente busca alternativas para reduzir o esforço da compra. Ele costuma ligar diretamente para o restaurante, procurar informações nas avaliações do Google, acessar o iFood para verificar cardápio e preços ou simplesmente escolher um concorrente cuja jornada seja mais rápida e intuitiva. Clientes antigos frequentemente continuam comprando pela confiança construída ao longo dos anos, mas clientes novos tendem a desistir diante de pequenas dificuldades. O diagnóstico também identificou que muitos consumidores acabam permanecendo no iFood pela praticidade, mesmo quando a empresa deseja migrá-los para canais próprios, como o WhatsApp Business, reduzindo a dependência da plataforma. | E7: A dor percebida pelo cliente não costuma ser verbalizada em termos técnicos. Ela aparece em comentários simples que refletem frustração durante a jornada de compra. Expressões compatíveis com o cenário identificado nas reuniões incluem: "Não consegui falar com ninguém." "Demoraram para atender." "Não achei o cardápio." "Não sabia quanto custava." "Achei que tinham fechado." "No iFood foi mais fácil pedir." "Quem me atendeu parecia sem paciência." O teste de cliente oculto confirmou dificuldades como espera elevada, falta de informações sobre produtos, conversas paralelas durante o atendimento telefônico e tom de voz considerado ríspido, reforçando críticas já presentes nas avaliações online. | F7: A causa do problema não está na qualidade da marca ou na ausência de mercado. Ela resulta da combinação de fatores operacionais e digitais que se acumularam ao longo do tempo. Entre os principais fatores identificados durante a consultoria estão: baixa maturidade digital; ausência de rotina para gestão de reputação online; inconsistência entre os canais digitais; atendimento telefônico sem protocolo padronizado; dependência excessiva do iFood; adoção tardia de ferramentas como WhatsApp Business; dificuldade em apresentar corretamente o portfólio de produtos, especialmente marmitas. Em outras palavras, o negócio possui valor percebido pela tradição, mas ainda não transformou esse patrimônio em uma operação preparada para competir no ambiente digital. | G7: Esse problema é constante. Todos os dias novos consumidores pesquisam restaurantes antes de decidir onde comprar, enquanto clientes recorrentes avaliam cada interação para decidir se continuarão comprando da mesma empresa. Cada ligação mal conduzida, avaliação sem resposta, dificuldade para encontrar informações ou atendimento demorado representa uma oportunidade perdida de venda ou fidelização. Por isso, durante o planejamento, foi definida como prioridade a reorganização da presença digital, a implementação do WhatsApp Business, a padronização do atendimento e a gestão ativa das avaliações antes de ampliar os investimentos em mídia paga. | H7: Dona Marlene — 58 anos | Moradora de São Vicente | Aposentada (ou comerciante/autônoma) | Cliente tradicional da região Dona Marlene mora em São Vicente há décadas e conhece a Mina Pizza desde muito antes do crescimento dos aplicativos de delivery. Ela não é uma consumidora que busca novidades gastronômicas toda semana; prefere comprar de empresas que conhece, que transmitem confiança e que já fazem parte da rotina da família. Para ela, escolher um restaurante não é apenas uma decisão racional baseada em preço, mas uma forma de evitar riscos e garantir que todos em casa ficarão satisfeitos. Sua rotina é bastante previsível. Durante a semana, procura refeições práticas para evitar cozinhar, principalmente nos dias mais corridos. Nos finais de semana, costuma pedir pizza para reunir filhos, netos ou amigos. Ela valoriza estabelecimentos que entregam comida saborosa, porções bem servidas e um atendimento cordial. Quando encontra um lugar que corresponde às suas expectativas, tende a permanecer cliente por muitos anos. Do ponto de vista psicológico, Dona Marlene busca segurança e estabilidade. Ela prefere empresas que demonstram organização, respeito e continuidade. Mudanças bruscas, excesso de informalidade ou experiências confusas geram desconforto. Ela acredita que uma empresa tradicional deve evoluir sem perder sua essência. Seu processo de decisão é influenciado por confiança, hábito e prova social. Antes de experimentar um restaurante desconhecido, costuma verificar avaliações no Google ou pedir recomendações. Se encontra comentários negativos recorrentes sobre atendimento ou qualidade, tende a desistir da compra. Ao contrário, quando vê boas avaliações, fotos reais e respostas educadas da empresa, sente maior segurança para realizar o pedido. Esse comportamento está alinhado à prioridade dada, nas reuniões, à gestão ativa das avaliações e da reputação online. Embora utilize tecnologia diariamente, sua relação com ela é funcional. Usa WhatsApp com frequência para conversar com familiares e considera esse o canal mais confortável para fazer pedidos. Também realiza pesquisas no Google quando procura informações sobre um estabelecimento, mas não deseja enfrentar processos complicados, cadastros extensos ou múltiplos aplicativos. A preferência por uma jornada simples e por canais próprios, especialmente o WhatsApp Business, foi destacada como prioridade estratégica durante a consultoria. Quando pensa na Mina Pizza, Dona Marlene enxerga uma empresa tradicional, conhecida na cidade e associada a boas lembranças. No entanto, espera perceber sinais claros de modernização. Ela deseja encontrar informações atualizadas no Google, visualizar fotos de qualidade, acessar facilmente o cardápio e receber um atendimento educado e eficiente. Se essas expectativas não forem atendidas, começa a comparar a experiência com concorrentes que oferecem uma jornada mais organizada. Sua maior frustração não é pagar um pouco mais por uma refeição de qualidade; é sentir que precisa fazer esforço para comprar. Ligações demoradas, falta de informações, dificuldade para descobrir os pratos disponíveis ou um atendimento impessoal fazem com que questione se a empresa ainda acompanha as necessidades dos clientes. Em contrapartida, quando a experiência é positiva, Dona Marlene torna-se uma forte promotora da marca. Ela recomenda a Mina Pizza para familiares, vizinhos e amigos, volta a comprar com frequência e contribui para fortalecer a reputação construída ao longo dos anos. Esse potencial de fidelização e recomendação reforça a estratégia definida nas reuniões de priorizar a retenção da base atual, aumentar a frequência de compra e combinar tradição com modernização da experiência do cliente.
B9: ALTERNATIVAS | E9: PORQUÊ
A10: Aspecto | B10: Diretas | C10: Indiretas | D10: Substitutas | E10: Motivo (Evento Gatilho) | F10: Diferencial | G10: Benefício Curto Prazo | H10: Benefício Longo Prazo
A11: Detalhamento | B11: As alternativas diretas são empresas que disputam exatamente o mesmo espaço mental do consumidor: quando ele decide pedir uma pizza, uma marmita ou uma refeição pronta na região de São Vicente. O principal concorrente identificado durante a consultoria foi o Império da Pizza, que possui forte presença no Google, Instagram e iFood, além de operar mais de uma unidade física. Seu diferencial está na consistência da presença digital e na facilidade de ser encontrado quando o consumidor pesquisa por pizzarias na região. Outro concorrente relevante é o Café com Pizza, que apresenta alto volume de avaliações e boa exposição no iFood. Apesar de possuir um posicionamento mais genérico, sua presença constante nas plataformas digitais faz com que participe diretamente da decisão de compra do consumidor. A Big Família foi considerada a principal referência aspiracional para a Mina Pizza. O modelo de negócio, que combina almoço, marmitas e pizzas, é bastante semelhante ao objetivo estratégico definido para a empresa. Além disso, sua comunicação, identidade visual e presença digital demonstram um nível de maturidade superior, tornando-a um benchmark para futuras ações. Esses concorrentes competem diretamente pelos mesmos clientes, horários de consumo, localização geográfica e intenção de compra. | C11: As alternativas indiretas atendem à mesma necessidade principal — alimentar-se com praticidade — porém utilizando propostas diferentes. Entre elas estão restaurantes especializados em marmitas, self-service, comida caseira, lanchonetes, hamburguerias, pastelarias e outros estabelecimentos que oferecem refeições prontas para almoço ou jantar. O próprio diagnóstico apontou que a expansão das marmitas representa uma oportunidade justamente porque o consumidor não procura apenas "pizza"; durante a semana ele busca resolver rapidamente o almoço. Essa mudança de comportamento foi considerada uma das principais oportunidades de crescimento da Mina Pizza. Também entram nessa categoria os estabelecimentos fortemente posicionados dentro do iFood, que aparecem antes da Mina Pizza graças ao investimento em mídia, avaliações e otimização da plataforma. | D11: As alternativas substitutas mudam completamente a lógica de consumo. O cliente pode decidir cozinhar em casa, comprar refeições prontas em supermercados, consumir alimentos congelados ou recorrer a conveniências e padarias próximas. Outra alternativa substituta é simplesmente optar por uma refeição mais simples para evitar custos ou esforço de decisão. Na prática, quando a jornada de compra da Mina Pizza apresenta atritos — dificuldade para localizar o restaurante, atendimento lento, ausência de informações claras ou canais pouco intuitivos — o consumidor tende a abandonar a intenção inicial e escolher a solução que exigir menos esforço. Foi exatamente por esse motivo que, durante a consultoria, foi reforçado o princípio de experiência do usuário de "não me faça pensar", simplificando a jornada por meio de canais como WhatsApp Business, cardápios organizados e informações facilmente acessíveis. | E11: O cliente não acorda querendo comprar uma pizza ou uma marmita; ele busca resolver uma situação específica do seu dia. Durante a semana, o gatilho mais comum é a falta de tempo. Depois de um dia de trabalho, ele quer uma refeição pronta, saborosa e confiável, sem precisar cozinhar ou perder tempo escolhendo entre dezenas de opções. No horário do almoço, procura uma comida que transmita a sensação de refeição caseira, com rapidez e bom custo-benefício. Nos finais de semana, o gatilho muda. A pizza representa um momento de convivência: reunir a família, receber amigos ou simplesmente transformar uma noite comum em uma ocasião agradável. Nesses momentos, o cliente evita correr riscos escolhendo um restaurante desconhecido e tende a recorrer a marcas que já fazem parte da sua história. Outro gatilho importante identificado nas reuniões é a busca por praticidade. Quando o consumidor encontra facilmente o restaurante no Google, acessa um cardápio organizado, faz o pedido rapidamente pelo WhatsApp e recebe um atendimento cordial, a decisão de compra se torna quase automática. | F11: O maior diferencial competitivo da Mina Pizza não é apenas vender pizzas, marmitas ou pastéis. É possuir uma história autêntica construída ao longo de décadas, combinada com um projeto de modernização que preserva essa identidade. Enquanto muitos concorrentes precisam criar narrativas para transmitir tradição, a Mina Pizza possui um legado real que pode ser utilizado como elemento de diferenciação. Esse posicionamento foi reconhecido nas reuniões como uma vantagem estratégica relevante. Além da tradição, outros diferenciais fortalecem essa proposta: diversidade de produtos para diferentes momentos de consumo (pizza, marmitas e pastéis); reconhecimento local consolidado; relacionamento próximo com clientes recorrentes; potencial para oferecer uma experiência simples e eficiente por canais próprios, reduzindo a dependência de plataformas. Quando esses elementos são combinados com atendimento padronizado, boa gestão da reputação online e presença digital consistente, a empresa deixa de competir apenas por preço e passa a competir por confiança | G11: Os benefícios percebidos imediatamente pelo cliente são práticos e facilmente mensuráveis. Ele consegue encontrar a empresa com facilidade, visualizar informações atualizadas, acessar um cardápio organizado, realizar o pedido sem esforço e receber um atendimento mais rápido e cordial. Essas melhorias reduzem o tempo entre a intenção de compra e a conclusão do pedido, diminuem a insegurança durante a escolha e aumentam a satisfação logo na primeira experiência. Do ponto de vista emocional, o cliente sente tranquilidade ao perceber que está comprando de uma empresa organizada, acessível e preparada para atendê-lo. Grande parte das ações propostas durante a consultoria — implementação do WhatsApp Business, padronização do atendimento, atualização do Google Meu Negócio e organização da presença digital — foi planejada justamente para gerar esse ganho imediato. | H11: A transformação mais importante acontece ao longo do relacionamento. O cliente passa a enxergar a Mina Pizza não apenas como um restaurante tradicional, mas como a primeira opção quando pensa em refeições práticas e confiáveis na região. Essa percepção fortalece a fidelização, aumenta a frequência de compra e estimula recomendações espontâneas para familiares e amigos, reduzindo a necessidade de depender exclusivamente de promoções ou mídia paga para gerar vendas. Para a empresa, isso representa uma base de clientes mais sólida, maior previsibilidade de receita e crescimento sustentado por reputação, relacionamento e recorrência. Esse objetivo está diretamente alinhado à estratégia definida nas reuniões: fortalecer canais próprios, aumentar a retenção da base atual e utilizar a tradição da marca como principal ativo competitivo, apoiado por uma operação digital mais eficiente.
B13: TESTE DE VALOR
A14: Aspecto | B14: PUV (Proposta Única de Valor) | C14: Problema Definido | D14: Como Alivia a Dor | E14: Ganho Prometido | F14: Ganhos Intangíveis | G14: Consciência do Público
A15: Detalhamento | B15: "A tradição de São Vicente, agora com uma experiência de pedido simples, rápida e confiável para quem quer pizzas, marmitas e refeições de qualidade sem abrir mão da confiança construída ao longo de décadas." Essa proposta reúne os principais diferenciais identificados nas reuniões: tradição comprovada; reconhecimento local; variedade de refeições para diferentes momentos de consumo; modernização da jornada de compra; foco na confiança e na recorrência. Ela evita competir apenas por preço e posiciona a Mina Pizza como uma marca que oferece segurança, praticidade e continuidade. | C15: O cliente deseja uma refeição de qualidade, mas encontra dificuldades para identificar rapidamente um restaurante que reúna confiança, praticidade e uma boa experiência de atendimento. Embora a Mina Pizza já possua credibilidade construída ao longo dos anos, sua presença digital, seus canais de atendimento e parte da experiência operacional ainda não refletem plenamente essa reputação. Isso faz com que novos consumidores encontrem concorrentes com mais facilidade, enquanto clientes antigos percebam atritos que reduzem a frequência de compra. Esse diagnóstico foi recorrente ao longo das reuniões, especialmente em relação ao Google Meu Negócio, atendimento telefônico, gestão das avaliações e canais digitais. | D15: A proposta da Mina Pizza reduz o esforço necessário para decidir e realizar um pedido. O cliente encontra facilmente a empresa no Google, acessa um cardápio organizado, escolhe entre pizza, marmitas ou pastéis conforme sua necessidade, realiza o pedido por um canal simples — preferencialmente o WhatsApp — e recebe um atendimento mais padronizado e acolhedor. Ao mesmo tempo, a tradição da marca reduz a insegurança comum ao experimentar um restaurante desconhecido. O cliente sente que está comprando de uma empresa consolidada, que faz parte da história da cidade e que agora entrega uma experiência compatível com os padrões atuais. As ações recomendadas na consultoria, como implantação do WhatsApp Business, organização do Google Meu Negócio, protocolo de atendimento e fortalecimento da reputação online, foram justamente planejadas para eliminar esses pontos de atrito. | E15: Os ganhos tangíveis para o cliente incluem: menor tempo para concluir um pedido; maior facilidade para encontrar informações; atendimento mais rápido e organizado; variedade de opções para diferentes momentos de consumo; maior confiança na decisão de compra. Para a empresa, os ganhos esperados são: aumento da frequência de compra; maior retenção da base atual; crescimento das vendas de marmitas; fortalecimento dos canais próprios; redução gradual da dependência do iFood; maior eficiência dos investimentos em mídia paga após a correção dos fundamentos digitais. | F15: Os benefícios mais valiosos da proposta são emocionais e relacionais. O cliente volta a sentir que compra de uma empresa confiável, organizada e presente em sua rotina. A tradição deixa de ser apenas uma lembrança do passado e passa a representar uma escolha segura também no presente. Com o tempo, fortalece-se a sensação de pertencimento: a Mina Pizza deixa de ser apenas um restaurante e passa a ocupar um espaço na memória afetiva da comunidade, tornando-se a opção natural para diferentes ocasiões. Para a empresa, isso significa uma reputação mais sólida, maior autoridade regional, fidelização espontânea e aumento das indicações boca a boca — ativos difíceis de replicar apenas com investimento em publicidade. | G15: Nível de consciência: Médio O cliente já sabe que precisa de uma refeição prática e conhece boa parte das alternativas disponíveis. Ele também reconhece a Mina Pizza como uma marca tradicional. No entanto, ainda não percebe completamente a transformação que a empresa está realizando nem os novos diferenciais relacionados à experiência digital, às marmitas, ao atendimento e à facilidade de compra. Por isso, a comunicação deve demonstrar continuamente que a tradição permanece, mas a experiência evoluiu. O posicionamento de "tradição redescoberta" definido durante a consultoria atende exatamente a esse objetivo: reduzir a distância entre a imagem histórica da marca e a experiência moderna que se deseja oferecer.
B17: AVALIAÇÃO DE PROPOSTA | F17: IMPACTO
A18: Aspecto | B18: Intensidade do Sonho | C18: Probabilidade de Sucesso | D18: Tempo Necessário | E18: Esforço Necessário | F18: Magnitude | G18: Frequência | H18: Custo de Troca | I18: Custo de Não Mudar
A19: Detalhamento | B19: Alta O cliente não sonha, necessariamente, em comprar uma pizza. O sonho é mais profundo: ele deseja ter uma refeição saborosa, prática e confiável para compartilhar com quem gosta, sem preocupação com qualidade, atraso ou atendimento. Esse desejo está presente de forma recorrente na rotina do público identificado durante a consultoria. A Mina Pizza atende tanto momentos cotidianos (almoço e jantar) quanto ocasiões especiais (encontros familiares e finais de semana), ampliando a relevância da marca na vida do consumidor. Além disso, existe um componente emocional importante: muitos clientes cresceram consumindo a marca e desejam continuar vivendo essa experiência com a mesma confiança de antes, agora aliada a uma operação mais moderna. | C19: Alta A proposta apresenta elevada probabilidade de sucesso porque não depende da criação de um novo hábito de consumo. Ela fortalece um comportamento que já existe. Durante o diagnóstico, verificou-se que a Mina Pizza possui ativos competitivos difíceis de replicar: marca consolidada há décadas; reconhecimento regional; clientes recorrentes; boa avaliação no iFood; estrutura operacional capaz de atender diferentes categorias de produtos. Os principais desafios identificados não estão relacionados ao produto, mas à execução: organização dos canais digitais, padronização do atendimento, gestão da reputação online e fortalecimento dos canais próprios. Essas ações foram priorizadas justamente por serem de alto impacto e relativamente baixo esforço. Como a empresa já possui confiança do mercado, a modernização da experiência tende a potencializar esse patrimônio em vez de exigir uma mudança completa de posicionamento. | D19: Curto Prazo Parte dos resultados pode ser percebida rapidamente após a implementação das melhorias recomendadas. Entre eles: aumento da facilidade para encontrar a empresa; melhora da percepção da marca; crescimento do contato via WhatsApp; aumento da taxa de conversão; redução do atrito durante o pedido. Já resultados como fortalecimento da fidelização, aumento da recorrência, crescimento do ticket médio e redução da dependência do iFood exigem continuidade e disciplina operacional, mas começam a ser construídos desde as primeiras mudanças. Essa lógica foi refletida no plano de ação definido nas reuniões, que priorizou intervenções de baixo esforço e alto impacto antes da expansão dos investimentos em mídia. | E19: Normal Para o cliente, o esforço tende a ser mínimo: a jornada fica mais simples, com acesso facilitado às informações e canais de atendimento. Para a empresa, entretanto, será necessário manter disciplina na execução das rotinas definidas durante a consultoria, como: responder avaliações no Google e no iFood; atualizar continuamente o Google Meu Negócio; manter o Instagram ativo; utilizar o WhatsApp Business como canal principal; padronizar o atendimento; fortalecer campanhas de mídia baseadas em prova social; acompanhar indicadores de conversão e retenção. Essas ações não exigem mudanças estruturais profundas, mas requerem consistência. O sucesso dependerá mais da qualidade da execução do que da complexidade das iniciativas. | F19: Alta O impacto da proposta da Mina Pizza vai além da venda de refeições. Ela transforma a forma como o cliente se relaciona com a marca. Ao modernizar sua presença digital, organizar seus canais de atendimento e fortalecer a experiência de compra, a empresa reduz atritos que hoje comprometem tanto a aquisição de novos consumidores quanto a retenção da base fiel. Para o cliente, isso significa encontrar uma empresa conhecida, confiável e muito mais fácil de acessar. Para o negócio, significa converter décadas de reputação em crescimento sustentável. As reuniões mostraram que a empresa já possui ativos relevantes — tradição, reconhecimento regional, boa avaliação no iFood e um público fiel —, mas ainda não captura todo esse valor por limitações na operação digital. | G19: Diária O problema aparece todos os dias. Todos os dias consumidores pesquisam restaurantes no Google, avaliam comentários, comparam cardápios, escolhem canais de atendimento e decidem onde realizar seus pedidos. Da mesma forma, clientes antigos avaliam continuamente a experiência oferecida pela empresa. Cada pedido representa uma nova oportunidade de fortalecer ou enfraquecer a confiança construída ao longo de décadas. Foi justamente por isso que a consultoria priorizou ações permanentes como: responder avaliações; atualizar informações da empresa; manter presença ativa nas redes sociais; fortalecer o WhatsApp Business; padronizar o atendimento. | H19: Baixo para o cliente | Moderado para a empresa Para o cliente Adotar a nova experiência praticamente não exige esforço. Ele continua comprando da mesma marca que conhece, apenas utilizando canais mais simples e eficientes. Não precisa aprender um novo serviço nem alterar seus hábitos de consumo. Para a empresa O investimento está concentrado em execução e organização. As mudanças identificadas durante a consultoria envolvem principalmente: gestão contínua da reputação online; organização dos canais digitais; atualização das informações institucionais; treinamento da equipe de atendimento; produção recorrente de conteúdo; utilização consistente do WhatsApp Business; acompanhamento de indicadores. Essas iniciativas demandam disciplina operacional mais do que grandes investimentos financeiros. | I19: Muito Alto Este é o ponto mais crítico identificado durante o diagnóstico. Caso a Mina Pizza mantenha o modelo atual, os riscos tendem a aumentar progressivamente. No curto prazo: perda de novos clientes para concorrentes mais organizados digitalmente; dificuldade para converter pesquisas em vendas; continuidade das avaliações sem resposta; dependência crescente do iFood. No médio prazo: redução da frequência de compra dos clientes tradicionais; aumento do custo de aquisição de clientes; necessidade crescente de promoções para competir. No longo prazo: enfraquecimento gradual da marca perante novas gerações; perda do patrimônio construído ao longo de décadas; redução da competitividade regional. Esses riscos foram amplamente discutidos durante as reuniões, especialmente em relação à dependência de plataformas, à reputação digital e à necessidade de fortalecer canais próprios antes de ampliar investimentos em mídia paga.

Sheet LINHA EDITORIAL
B1: CATEGORIAS
B2: Dor e Alívio | C2: Escolha Certa | D2: Vida Nova
A3: PILAR 1 | B3: Problemas Comuns | C3: Tipos de Colchões | D3: Benefícios Imediatos
A4: PILAR 2 | B4: Impactos na Rotina | C4: Guia de Compra | D4: Estilo de Vida
A5: PILAR 3 | B5: Sinais de Troca | C5: Prova Social | D5: Qualidade de Vida
B7: =B2 -> Dor e Alívio
B8: =B3 -> Problemas Comuns | C8: =B4 -> Impactos na Rotina | D8: =B5 -> Sinais de Troca
A9: TEMA | B9: Dores ao Acordar | C9: Cansaço Diário | D9: Colchão Vencido
B10: Colchão Afundado | C10: Mau Humor Matinal | D10: Barulho ao Virar
B11: Sono Interrompido | C11: Falta de Energia | D11: Marcas no Corpo
B13: =C2 -> Escolha Certa
B14: =C3 -> Tipos de Colchões | C14: =C4 -> Guia de Compra | D14: =C5 -> Prova Social
A15: TEMA | B15: Espuma vs Molas | C15: Como Escolher | D15: Depoimentos Reais
B16: Firmeza Ideal | C16: Erros Frequentes | D16: Antes e Depois
B17: Altura e Conforto | C17: Testar na Loja | D17: Histórias de Troca
B19: =D2 -> Vida Nova
B20: =D3 -> Benefícios Imediatos | C20: =D4 -> Estilo de Vida | D20: =D5 -> Qualidade de Vida
A21: TEMA | B21: Dormir Melhor Hoje | C21: Quarto dos Sonhos | D21: Sono e Saúde
B22: Conforto Renovado | C22: Autocuidado Noturno | D22: Rendimento Pessoal
B23: Acordar Leve | C23: Bem-estar Diário | D23: Relação com o Sono

Sheet CLIENTES
B1: MELHOR CLIENTE
A2: Aspecto | B2: QUEM É ESTE CLIENTE | C2: DIFERENÇAS | D2: MOTIVAÇÃO | E2: CONSCIÊNCIA | F2: CONTATO | G2: FREQUÊNCIA | H2: POTENCIAL
A3: Detalhamento | B3: Mulher, 38 anos, fisioterapeuta clínica em Campinas (SP), classe média alta, sensível à saúde e qualidade de vida. | C3: Muito bem informada, comparou várias marcas antes de decidir, deu feedback técnico após uso, virou embaixadora informal da marca. | D3: Sofria com dores lombares crônicas, pacientes sempre perguntavam sobre colchões. Buscava algo com suporte firme, feito para seu biotipo. | E3: Ciente da solução e do produto, já pesquisava colchões ortopédicos e personalizados. | F3: Descobriu via vídeo no YouTube sobre ergonomia do sono, clicou no link e agendou atendimento consultivo. | G3: Fez uma compra premium e depois indicou para 5 pacientes. Mandou 3 mensagens de agradecimento. | H3: Alto – tem influência no segmento de saúde, virou cliente recorrente para outros produtos (travesseiro, base, colchão infantil).
B5: CLIENTE MAIS ANTIGO
A6: Aspecto | B6: QUEM É ESTE CLIENTE | C6: DIFERENÇAS | D6: MOTIVAÇÃO | E6: CONSCIÊNCIA | F6: CONTATO | G6: FREQUÊNCIA | H6: POTENCIAL
A7: Detalhamento | B7: Casal, 42 e 39 anos, empresários no setor de franquias, alto poder aquisitivo, moram em Alphaville (SP). | C7: Compraram 3 colchões completos: suíte máster, casa de praia e para o filho. Sem barganha, com upgrades. | D7: Reformaram a casa e queriam uma experiência de sono personalizada para cada ambiente. | E7: Totalmente conscientes – chegaram com referências, queriam “o melhor colchão do Brasil”. | F7: Indicação de arquiteta parceira da marca. | G7: Compraram 3 vezes em 90 dias e recomendaram para outro casal (ticket semelhante). | H7: Alto – têm poder de compra, rede social com lifestyle forte, valorizaram experiência personalizada e exclusividade do atendimento.
B9: CLIENTE MAIS LUCRATIVO
A10: Aspecto | B10: QUEM É ESTE CLIENTE | C10: DIFERENÇAS | D10: MOTIVAÇÃO | E10: CONSCIÊNCIA | F10: CONTATO | G10: FREQUÊNCIA | H10: POTENCIAL
A11: Detalhamento | B11: Homem, 67 anos, aposentado, mora em Belo Horizonte. Cliente desde 2017. Conservador, detalhista, muito fiel. | C11: Exige explicações técnicas profundas, confia na marca. Telefone fixo, não interage em redes, mas liga a cada 2 anos para ajustes. | D11: Comprou após indicação do ortopedista. Tinha hérnia de disco e queria um colchão que aliviasse a dor. | E11: Ciente do problema e da solução, mas desconfiava de marcas populares. Queria algo confiável. | F11: Descobriu após indicação boca a boca e buscou no Google, depois ligou para a loja. | G11: Comprou colchão em 2017, base em 2019, e nova espuma sob medida em 2022. | H11: Médio – apesar da idade e do ticket limitado, tem influência sobre outros aposentados e familiares (já indicou a filha e o cunhado).
B13: O CLIENTE DOS SONHOS
A14: Aspecto | B14: QUEM É ESTE CLIENTE | C14: DIFERENÇAS | D14: MOTIVAÇÃO | E14: CONSCIÊNCIA | F14: CONTATO | G14: FREQUÊNCIA | H14: POTENCIAL
A15: Detalhamento | B15: Mulher, 33 anos, influenciadora digital no nicho de autocuidado e bem-estar, com 180k seguidores no Instagram, mora em Florianópolis. | C15: Além de comprar, documentou a jornada do colchão em posts e stories, gerando 7 novos leads de alto valor em uma semana. | D15: Busca constante por otimizar performance e qualidade de vida. Já tinha testado colchões gringos e queria algo nacional de alto nível. | E15: Totalmente consciente – buscava uma marca nacional premium e já entendia sobre densidade, materiais e sono profundo. | F15: Veio por tráfego orgânico de Instagram, depois acessou o site, leu o blog e chamou no WhatsApp. | G15: Comprou colchão, base, travesseiros e está testando nova espuma para divulgar num review. | H15: Altíssimo – gera autoridade, conversão orgânica e agrega valor aspiracional à marca. Pode ser parceira recorrente ou rosto da campanha.
B17: EXPLICAÇÃO
A18: Aspecto | B18: QUEM É ESTE CLIENTE | C18: DIFERENÇAS | D18: MOTIVAÇÃO | E18: CONSCIÊNCIA | F18: CONTATO | G18: FREQUÊNCIA | H18: POTENCIAL
A19: Detalhamento | B19: Descreva os atributos objetivos e estruturais do cliente. Para B2B: Porte da empresa (faturamento, número de funcionários) Setor de atuação Cargo do decisor Tempo de mercado Para B2C: Faixa etária Gênero Profissão ou renda Estilo de Vida | C19: O que torna esse cliente diferente dos demais que você atende. Pode ser um comportamento, uma atitude ou uma característica inesperada. Exemplos: É extremamente engajado Decide rápido Sempre traz feedbacks úteis Já conhecia o problema profundamente Tem comportamento colaborativo | D19: O gatilho real que fez esse cliente tomar a decisão de compra. O que aconteceu no mundo dele que gerou ação? Exemplos: Tinha urgência para resolver um problema Buscava redução de custo Queria melhorar um processo Precisava de um parceiro de confiança Estava frustrado com fornecedor anterior | E19: Qual era o nível de consciência dele no momento da compra? Níveis (baseados em Eugene Schwartz): Inconsciente – nem sabia que tinha um problema Ciente do problema – sabia que tinha um problema, mas não buscava solução Ciente da solução – sabia que havia saídas, mas não conhecia sua empresa Ciente do produto – já conhecia sua empresa/produto Totalmente consciente – já queria comprar, só faltava executar | F19: Por onde esse cliente te encontrou ou chegou até sua solução? Pode ter sido uma rede social, campanha paga, indicação, conteúdo, evento, anúncio, etc. Exemplos: Veio pelo Instagram após um reels viral Indicação de cliente atual Encontrou pelo Google procurando por “solução X” Conversou num evento e depois voltou pelo site | G19: Com que regularidade esse cliente interage com sua marca: compra, renova, consome conteúdo, indica ou responde? Exemplos: Comprou 3x em 6 meses Assinatura recorrente mensal Responde a todas as comunicações Entrou em 2 produtos diferentes Participa de lives ou eventos | H19: Avalie se esse cliente pode crescer com você — comprando mais, indicando outros ou evoluindo de produto. Exemplos: Tem filiais ou outras áreas Está crescendo e pode escalar Está aberto a testar novos serviços Tem rede de influência Já indicou outros clientes

Sheet CANAIS
A1: INSTAGRAM | B1: CANAL
B2: =$A$1 & "1" -> INSTAGRAM1 | C2: =$A$1 & "2" -> INSTAGRAM2 | D2: =$A$1 & "3" -> INSTAGRAM3 | E2: =$A$1 & "4" -> INSTAGRAM4 | F2: =$A$1 & "5" -> INSTAGRAM5 | G2: =$A$1 & "6" -> INSTAGRAM6 | H2: =$A$1 & "7" -> INSTAGRAM7
A3: Público | B3: {=IFERROR(INDEX('INDICE DE CANAIS'!B:B, MATCH(B2, 'INDICE DE CANAIS'!A:A, 0)), "—")} -> Apressados e Visuais (16–40) | C3: {=IFERROR(INDEX('INDICE DE CANAIS'!B:B, MATCH(C2, 'INDICE DE CANAIS'!A:A, 0)), "—")} -> Analíticos e Silenciosos (25–55) | D3: {=IFERROR(INDEX('INDICE DE CANAIS'!B:B, MATCH(D2, 'INDICE DE CANAIS'!A:A, 0)), "—")} -> Em busca de pertencimento (18–35) | E3: {=IFERROR(INDEX('INDICE DE CANAIS'!B:B, MATCH(E2, 'INDICE DE CANAIS'!A:A, 0)), "—")} -> Práticos do Dia a Dia (20–60) | F3: {=IFERROR(INDEX('INDICE DE CANAIS'!B:B, MATCH(F2, 'INDICE DE CANAIS'!A:A, 0)), "—")} -> Família e Rotina (25–55) | G3: {=IFERROR(INDEX('INDICE DE CANAIS'!B:B, MATCH(G2, 'INDICE DE CANAIS'!A:A, 0)), "—")} -> Curiosos e Entusiastas (16–50) | H3: {=IFERROR(INDEX('INDICE DE CANAIS'!B:B, MATCH(H2, 'INDICE DE CANAIS'!A:A, 0)), "—")} -> Caçadores de Oportunidades (18–60)
A4: QUER USAR? | B4: SIM | C4: SIM | D4: SIM | E4: SIM | F4: SIM | G4: NÃO | H4: SIM
A5: Detalhamento | B5: {=IFERROR(INDEX('INDICE DE CANAIS'!C:C, MATCH(B2, 'INDICE DE CANAIS'!A:A, 0)), "—")} -> São pessoas que consomem conteúdo em intervalos curtos ao longo do dia, como durante o transporte, pausas no trabalho ou no banheiro. Preferem Reels de até 15 segundos, vídeos com legenda automática e ritmo acelerado. Não têm paciência para conteúdo lento ou complexo. Se algo chamar atenção nos primeiros segundos, elas param. O pensamento dominante é: “me mostra logo o que eu ganho com isso”. Normalmente clicam apenas se o botão ou mensagem for mais chamativo que o próprio conteúdo. Esse público é excelente para produtos de giro rápido, promoções diretas, reviews e humor cotidiano. | C5: {=IFERROR(INDEX('INDICE DE CANAIS'!C:C, MATCH(C2, 'INDICE DE CANAIS'!A:A, 0)), "—")} -> Esse grupo é formado por pessoas mais racionais, que observam muito antes de agir. Costumam acessar o Instagram no início da manhã ou no final do dia, e valorizam conteúdos que ensinam algo útil. Carrosséis explicativos, análises, frameworks e bastidores são os formatos que mais atraem. Eles raramente curtem ou comentam, mas salvam e voltam depois. Clicam mais em DMs, botões discretos e CTAs bem posicionados. São ideais para negócios B2B, serviços técnicos, consultorias e produtos de alto valor com foco em argumento lógico. | D5: {=IFERROR(INDEX('INDICE DE CANAIS'!C:C, MATCH(D2, 'INDICE DE CANAIS'!A:A, 0)), "—")} -> Esse público é movido por aspiração e identidade. Querem encontrar referências de quem já chegou onde eles querem estar. Consomem frases com fundo preto, rotinas editadas, lifestyle e narrativas de superação. Estão presentes principalmente na madrugada e nas manhãs. Eles pensam: “quero ser alguém, quem já chegou lá?”. Engajam através de marcações, comentários de identificação e salvamentos emocionais. Conectam muito bem com conteúdos que falam sobre propósito, mudança de vida, estética e liberdade. São ótimos para marcas com storytelling forte, produtos aspiracionais e influenciadores. | E5: {=IFERROR(INDEX('INDICE DE CANAIS'!C:C, MATCH(E2, 'INDICE DE CANAIS'!A:A, 0)), "—")} -> Formado por pessoas que usam o Instagram como ferramenta de solução, esse público valoriza conteúdos que resolvem problemas reais. Consomem antes e depois, tutoriais curtos, dicas rápidas e explicações simples. Estão ativos ao longo do expediente e aos sábados. Pensam sempre: “isso resolve meu problema agora?”. Costumam clicar em stories com instruções claras, destaques de “como funciona” e enviar direct com dúvidas. São perfeitos para produtos de uso doméstico, alimentação, cuidados pessoais, serviços locais e soluções rápidas — inclusive papel higiênico. | F5: {=IFERROR(INDEX('INDICE DE CANAIS'!C:C, MATCH(F2, 'INDICE DE CANAIS'!A:A, 0)), "—")} -> Aqui temos mães, pais e cuidadores que consomem Instagram como extensão da vida familiar. Acessam a plataforma de manhã, antes do caos começar, ou à noite, quando a casa está em silêncio. Preferem conteúdo que ajude na rotina, sem exigir esforço mental. Se conectam com memes sobre filhos, reviews de produtos, dicas financeiras e soluções práticas para o dia a dia. Detestam jargões, enrolação e vídeos confusos. Clicam em stories com explicação leve, CTAs contextuais e depoimentos reais. Perfeitos para nichos de lar, saúde, limpeza, alimentação e bem-estar familiar. | G5: {=IFERROR(INDEX('INDICE DE CANAIS'!C:C, MATCH(G2, 'INDICE DE CANAIS'!A:A, 0)), "—")} -> São usuários ativos e inquietos. Vivem zapeando o Instagram em busca de novidade. Gostam de bastidores, “como é feito”, testes de produto e comparativos visuais. Não necessariamente compram de imediato, mas são impactados por conteúdos intrigantes que despertam dúvida. Pensam: “quero saber mais, mesmo que não compre agora”. Engajam por salvamento ou comentário perguntando algo. São ótimos para nichos como tecnologia, cosméticos, alimentos e qualquer conteúdo que permita explorar bastidores ou diferenciais técnicos. | H5: {=IFERROR(INDEX('INDICE DE CANAIS'!C:C, MATCH(H2, 'INDICE DE CANAIS'!A:A, 0)), "—")} -> Esse público vive atrás de ofertas, novidades e condições especiais. Estão atentos a cupons, lançamentos e conteúdos com gatilhos de escassez ou urgência. Acessam o Instagram ao longo do dia, com mais força nas quintas e sextas. Pensam: “se eu não aproveitar isso agora, vou me arrepender”. Clicam imediatamente em botões chamativos, muitas vezes sem nem ler a legenda toda. Ideais para ecommerce, campanhas de lançamento, datas sazonais, produtos promocionais e qualquer conteúdo que envolva vantagem imediata.

Sheet INDICE DE CANAIS
A1: CANAL | B1: PÚBLICO | C1: DESCRIÇÃO
A2: INSTAGRAM1 | B2: Apressados e Visuais (16–40) | C2: São pessoas que consomem conteúdo em intervalos curtos ao longo do dia, como durante o transporte, pausas no trabalho ou no banheiro. Preferem Reels de até 15 segundos, vídeos com legenda automática e ritmo acelerado. Não têm paciência para conteúdo lento ou complexo. Se algo chamar atenção nos primeiros segundos, elas param. O pensamento dominante é: “me mostra logo o que eu ganho com isso”. Normalmente clicam apenas se o botão ou mensagem for mais chamativo que o próprio conteúdo. Esse público é excelente para produtos de giro rápido, promoções diretas, reviews e humor cotidiano.
A3: INSTAGRAM2 | B3: Analíticos e Silenciosos (25–55) | C3: Esse grupo é formado por pessoas mais racionais, que observam muito antes de agir. Costumam acessar o Instagram no início da manhã ou no final do dia, e valorizam conteúdos que ensinam algo útil. Carrosséis explicativos, análises, frameworks e bastidores são os formatos que mais atraem. Eles raramente curtem ou comentam, mas salvam e voltam depois. Clicam mais em DMs, botões discretos e CTAs bem posicionados. São ideais para negócios B2B, serviços técnicos, consultorias e produtos de alto valor com foco em argumento lógico.
A4: INSTAGRAM3 | B4: Em busca de pertencimento (18–35) | C4: Esse público é movido por aspiração e identidade. Querem encontrar referências de quem já chegou onde eles querem estar. Consomem frases com fundo preto, rotinas editadas, lifestyle e narrativas de superação. Estão presentes principalmente na madrugada e nas manhãs. Eles pensam: “quero ser alguém, quem já chegou lá?”. Engajam através de marcações, comentários de identificação e salvamentos emocionais. Conectam muito bem com conteúdos que falam sobre propósito, mudança de vida, estética e liberdade. São ótimos para marcas com storytelling forte, produtos aspiracionais e influenciadores.
A5: INSTAGRAM4 | B5: Práticos do Dia a Dia (20–60) | C5: Formado por pessoas que usam o Instagram como ferramenta de solução, esse público valoriza conteúdos que resolvem problemas reais. Consomem antes e depois, tutoriais curtos, dicas rápidas e explicações simples. Estão ativos ao longo do expediente e aos sábados. Pensam sempre: “isso resolve meu problema agora?”. Costumam clicar em stories com instruções claras, destaques de “como funciona” e enviar direct com dúvidas. São perfeitos para produtos de uso doméstico, alimentação, cuidados pessoais, serviços locais e soluções rápidas — inclusive papel higiênico.
A6: INSTAGRAM5 | B6: Família e Rotina (25–55) | C6: Aqui temos mães, pais e cuidadores que consomem Instagram como extensão da vida familiar. Acessam a plataforma de manhã, antes do caos começar, ou à noite, quando a casa está em silêncio. Preferem conteúdo que ajude na rotina, sem exigir esforço mental. Se conectam com memes sobre filhos, reviews de produtos, dicas financeiras e soluções práticas para o dia a dia. Detestam jargões, enrolação e vídeos confusos. Clicam em stories com explicação leve, CTAs contextuais e depoimentos reais. Perfeitos para nichos de lar, saúde, limpeza, alimentação e bem-estar familiar.
A7: INSTAGRAM6 | B7: Curiosos e Entusiastas (16–50) | C7: São usuários ativos e inquietos. Vivem zapeando o Instagram em busca de novidade. Gostam de bastidores, “como é feito”, testes de produto e comparativos visuais. Não necessariamente compram de imediato, mas são impactados por conteúdos intrigantes que despertam dúvida. Pensam: “quero saber mais, mesmo que não compre agora”. Engajam por salvamento ou comentário perguntando algo. São ótimos para nichos como tecnologia, cosméticos, alimentos e qualquer conteúdo que permita explorar bastidores ou diferenciais técnicos.
A8: INSTAGRAM7 | B8: Caçadores de Oportunidades (18–60) | C8: Esse público vive atrás de ofertas, novidades e condições especiais. Estão atentos a cupons, lançamentos e conteúdos com gatilhos de escassez ou urgência. Acessam o Instagram ao longo do dia, com mais força nas quintas e sextas. Pensam: “se eu não aproveitar isso agora, vou me arrepender”. Clicam imediatamente em botões chamativos, muitas vezes sem nem ler a legenda toda. Ideais para ecommerce, campanhas de lançamento, datas sazonais, produtos promocionais e qualquer conteúdo que envolva vantagem imediata.
A9: TIKTOK1 | B9: Jovens Viralizadores (15–24) | C9: São nativos da plataforma. Usam TikTok como principal rede social. Consomem entre 1 a 3 horas por dia. Interagem com tudo: trends, humor, storytelling exagerado, react, POV. Amam vídeos com cortes rápidos, música alta e textos sobrepostos. Compartilham com amigos, salvam para imitar, e fazem duetos. Não ligam para autoridade — querem identificação e entretenimento. O tom precisa ser informal, visualmente acelerado e com códigos de comunidade. Gatilhos como “você viu isso?” ou “ninguém fala sobre isso” funcionam bem.
A10: TIKTOK2 | B10: Criadores Iniciantes (20–35) | C10: Pessoas que querem crescer na plataforma. Estão aprendendo algoritmo, testando formatos e copiando tendências. Consomem muito conteúdo de bastidor, hack de engajamento, dicas de roteiro e edição. Preferem vídeos que ensinam “o que postar” ou “como viralizar”. Compartilham entre grupos e comentam tentando gerar visibilidade. O tom precisa ser direto, de bastidor, com CTA claro tipo: “salva esse roteiro” ou “testa isso no seu vídeo de amanhã”.
A11: TIKTOK3 | B11: Empreendedores Populares | C11: Donos de pequenos negócios, principalmente locais (barbearias, estúdios de unha, doces, brechós), que viralizaram com vídeos simples e querem mais. Estão aprendendo que o TikTok gera clientes. Gostam de ver vídeos de “antes e depois”, rotina, reação de clientes e desafios. Gravando no próprio celular, sem edição pesada. O tom ideal é descontraído, popular e espontâneo. Frases como “acompanha a rotina da loja hoje” ou “olha o que esse cliente pediu” engajam muito.
A12: TIKTOK4 | B12: Vendedores de Info ou Produto Digital | C12: Estão transformando o TikTok em vitrine de produtos digitais (ebooks, cursos, PLR, serviços). Usam CTAs fortes e técnicas de copy. Costumam repetir vídeos com leve variação de roteiro. Gostam de mostrar resultado, ping de venda, dashboard. O conteúdo performa quando o vídeo promete algo direto: “como eu fiz R$1.000 vendendo isso aqui”. Tom vendedor, objetivo e com visual apelativo. Gatilhos visuais como prints, barras de progresso, reações funcionam.
... A36: BLOG7 | B36: Leitor por Recomendação (qualquer idade) | C36: Chegou porque alguém mandou o link. Não está em busca ativa, mas topou o conteúdo por curiosidade. Lê com menor profundidade, mas se prender nos 10 primeiros segundos, pode consumir tudo. Prefere textos com storytelling, opinião e impacto. Esse público compartilha se se sentir representado. Gatilhos como “você já passou por isso?” ou “entenda esse ponto antes que seja tarde” funcionam bem. Ideal para artigos compartilháveis e tráfego social.
A37: EMAIL1
A38: EMAIL2
A39: EMAIL3
A40: EMAIL4
A41: EMAIL5
A42: EMAIL6
A43: EMAIL7

Sheet FORMATOS
A1: TEXTO CURTO | B1: FORMATOS
B2: =$A$1 & "1" -> TEXTO CURTO1 | C2: =$A$1 & "2" -> TEXTO CURTO2 | D2: =$A$1 & "3" -> TEXTO CURTO3 | E2: =$A$1 & "4" -> TEXTO CURTO4 | F2: =$A$1 & "5" -> TEXTO CURTO5 | G2: =$A$1 & "6" -> TEXTO CURTO6 | H2: =$A$1 & "7" -> TEXTO CURTO7
A3: Público | B3: {=IFERROR(INDEX('INDICE DE FORMATOS'!B:B, MATCH(B2, 'INDICE DE FORMATOS'!A:A, 0)), "—")} -> Insight | C3: {=IFERROR(INDEX('INDICE DE FORMATOS'!B:B, MATCH(C2, 'INDICE DE FORMATOS'!A:A, 0)), "—")} -> Diário | D3: {=IFERROR(INDEX('INDICE DE FORMATOS'!B:B, MATCH(D2, 'INDICE DE FORMATOS'!A:A, 0)), "—")} -> Pergunta | E3: {=IFERROR(INDEX('INDICE DE FORMATOS'!B:B, MATCH(E2, 'INDICE DE FORMATOS'!A:A, 0)), "—")} -> 1 Coisa | F3: {=IFERROR(INDEX('INDICE DE FORMATOS'!B:B, MATCH(F2, 'INDICE DE FORMATOS'!A:A, 0)), "—")} -> Texto Manifesto | G3: {=IFERROR(INDEX('INDICE DE FORMATOS'!B:B, MATCH(G2, 'INDICE DE FORMATOS'!A:A, 0)), "—")} -> Micro Case | H3: {=IFERROR(INDEX('INDICE DE FORMATOS'!B:B, MATCH(H2, 'INDICE DE FORMATOS'!A:A, 0)), "—")} -> Storytelling com Conteúdo
A4: QUER USAR? | B4: SIM | C4: SIM | D4: SIM | E4: SIM | F4: SIM | G4: SIM | H4: SIM
